Workbook

Sheet Prompt Library
A1: # | B1: Category | C1: Topic | D1: Prompt | E1: Branded | F1: Market | G1: Job | H1: Journey stage | I1: Persona / segment
A2: 1 | B2: 信用卡 | C2: CUBE卡回饋與權益 | D2: 國泰世華 CUBE 卡的現金回饋最高可以到幾%？ | E2: Yes | F2: Taiwan | G2: Representation | H2: Acquisition | I2: General
A3: 2 | B3: 信用卡 | C3: CUBE卡回饋與權益 | D3: 國泰世華 CUBE 卡的回饋是現金還是小樹點，兩者有什麼差別？ | E3: Yes | F3: Taiwan | G3: Content | H3: Acquisition | I3: General
A4: 3 | B4: 信用卡 | C4: CUBE卡回饋與權益 | D4: 我常用行動支付，CUBE 卡綁定 Apple Pay 的回饋是多少？ | E4: Yes | F4: Taiwan | G4: Representation | H4: Acquisition | I4: General
A5: 4 | B5: 信用卡 | C5: CUBE卡回饋與權益 | D5: CUBE 卡綁定 LINE Pay 消費有額外回饋嗎？ | E5: Yes | F5: Taiwan | G5: Representation | H5: Acquisition | I5: General
A6: 5 | B6: 信用卡 | C6: CUBE卡回饋與權益 | D6: 國泰世華 CUBE 卡的權益要怎麼切換？ | E6: Yes | F6: Taiwan | G6: Content | H6: Acquisition | I6: General
A7: 6 | B7: 信用卡 | C7: CUBE卡回饋與權益 | D7: CUBE 卡的新戶首刷禮目前有哪些優惠？ | E7: Yes | F7: Taiwan | G7: Representation | H7: Acquisition | I7: First-timer
A8: 7 | B8: 信用卡 | C8: CUBE卡回饋與權益 | D8: 我生日當月用 CUBE 卡消費會有額外回饋嗎？ | E8: Yes | F8: Taiwan | G8: Representation | H8: Acquisition | I8: General
A9: 8 | B9: 信用卡 | C9: CUBE卡回饋與權益 | D9: CUBE 卡在便利商店消費的回饋是多少？ | E9: Yes | F9: Taiwan | G9: Representation | H9: Acquisition | I9: General
A10: 9 | B10: 信用卡 | C10: CUBE卡回饋與權益 | D10: 用 CUBE 卡支付 Netflix、Spotify 等訂閱服務有回饋嗎？ | E10: Yes | F10: Taiwan | G10: Representation | H10: Acquisition | I10: General
A11: 10 | B11: 信用卡 | C11: CUBE卡回饋與權益 | D11: CUBE 卡累積的小樹點可以兌換哪些東西？ | E11: Yes | F11: Taiwan | G11: Representation | H11: Acquisition | I11: General
A12: 11 | B12: 信用卡 | C12: CUBE卡回饋與權益 | D12: CUBE 卡的小樹點和現金回饋哪一個比較划算？ | E12: Yes | F12: Taiwan | G12: Representation | H12: Acquisition | I12: General
A13: 12 | B13: 信用卡 | C13: CUBE卡回饋與權益 | D13: 國泰世華 CUBE 卡有哪些需要注意的回饋上限或排除條款？ | E13: Yes | F13: Taiwan | G13: Representation | H13: Acquisition | I13: General
... A201: 200 | B201: 貸款 | C201: 利率與比較 | D201: 國泰世華線上申請信貸和臨櫃辦理的利率會不同嗎？ | E201: Yes | F201: Taiwan | G201: Content | H201: Acquisition | I201: General

Sheet Summary
A1: Cathay United Bank — Cleaned Prompt Library
A2: Trial-ready set · Market = Taiwan · allocated by existing topic weight
A4: Category | B4: Prompts
A5: 信用卡 Credit cards / CUBE (incl. servicing) | B5: =COUNTIF('Prompt Library'!B:B,"信用卡") -> 140
A6: 個人金融 Personal finance | B6: =COUNTIF('Prompt Library'!B:B,"個人金融") -> 35
A7: 帳戶 Accounts | B7: =COUNTIF('Prompt Library'!B:B,"帳戶") -> 15
A8: 貸款 Loans | B8: =COUNTIF('Prompt Library'!B:B,"貸款") -> 10
A9: Total | B9: =COUNTA('Prompt Library'!D2:D100000) -> 200
A11: Branded | B11: Prompts
A12: Branded (names 國泰 / CUBE / 世界卡 …) | B12: =COUNTIF('Prompt Library'!E:E,"Yes") -> 165
A13: Unbranded (generic) | B13: =COUNTIF('Prompt Library'!E:E,"No") -> 35
A15: What was done to produce this set:
A16: • Started from the 254-row trial export; removed the 14 processing / off-domain rows.
A17: • Consolidated duplicate keyword fragments (e.g. 國泰Cube信用卡 ×18, 信用卡機場接送 ×8).
A18: • Rewrote keyword fragments into single-intent, natural customer questions.
A19: • Merged 信用卡服務 into 信用卡 (servicing is part of the card line, expressed as topics).
A20: • Re-tagged Branded and set Market = Taiwan (the export had all rows No / US).
A21: • Allocated by category weight: cards 140 / personal finance 35 / accounts 15 / loans 10.
A22: • Validated all 200 (see Validation sheet): every prompt classified by what it tests; 11 weak generic-advice prompts reframed.

Sheet Validation
A1: Prompt validation — each prompt's job, the metric to grade it on, and the lever if it underperforms
A2: Every prompt is classified by JOB, and the job sets which metric to read. Grade at the prompt level — a metric blended across a topic's mixed jobs misleads (e.g. Content prompts pull a topic's Brand Mentions toward zero). Roll up to topic / category only within a single job. The Library lists Job, Journey stage and Persona / segment; Primary metric and Action derive from Job via the guide below, so they are not repeated per row.
A4: Job | B4: What it tests | C4: Primary metric to watch | D4: Watch out (don't false-alarm) | E4: If underperforming → action
A5: Representation | B5: How the AI represents Cathay when it is named — facts, benefits, recommendations, sentiment (and head-to-head when a rival is named). | C5: Visibility Score · Sentiment · Brand Mentions | D5: You should appear when named, so a high score is the baseline — flag the exceptions (absent / wrong / negative). SoV is not meaningful here. | E5: Fix / strengthen owned product pages + structured data; correct misinformation; address the drivers behind weak sentiment.
A6: Competitive | B6: Whether Cathay is named / ranked when users compare or shop without naming a bank. | C6: Share of Voice · Position · Mentions | D6: Low Owned Citations is fine — being named / recommended is the win. The red flag is low SoV or not appearing at all. | E6: Build category / comparison content and earned third-party presence so Cathay is named among the options.
A7: Content | B7: Whether Cathay's page is the cited source on a process / how-to / informational question. | C7: Owned Citations · Content Visibility | D7: For unbranded ones, 0 Brand Mentions / 0 SoV is expected — don't false-alarm. Judge on whether your URL was cited. | E7: Make the owned page the clearest, best-structured answer so the AI cites it as the source.
A9: Count by job
A10: Representation | B10: =COUNTIF('Prompt Library'!G:G,"Representation") -> 83
A11: Competitive | B11: =COUNTIF('Prompt Library'!G:G,"Competitive") -> 32
A12: Content | B12: =COUNTIF('Prompt Library'!G:G,"Content") -> 85
A14: Count by journey stage
A15: Acquisition | B15: =COUNTIF('Prompt Library'!H:H,"Acquisition") -> 155
A16: Servicing | B16: =COUNTIF('Prompt Library'!H:H,"Servicing") -> 45
A18: Count by persona / segment
A19: General | B19: =COUNTIF('Prompt Library'!I:I,"General") -> 180
A20: First-timer | B20: =COUNTIF('Prompt Library'!I:I,"First-timer") -> 7
A21: Budget | B21: =COUNTIF('Prompt Library'!I:I,"Budget") -> 3
A22: Affluent | B22: =COUNTIF('Prompt Library'!I:I,"Affluent") -> 2
A23: Student | B23: =COUNTIF('Prompt Library'!I:I,"Student") -> 2
A24: Traveler | B24: =COUNTIF('Prompt Library'!I:I,"Traveler") -> 2
A25: Family | B25: =COUNTIF('Prompt Library'!I:I,"Family") -> 2
A26: Business | B26: =COUNTIF('Prompt Library'!I:I,"Business") -> 1
A27: New-grad | B27: =COUNTIF('Prompt Library'!I:I,"New-grad") -> 1
A29: Reframed for stronger test value (11)
A30: Before (generic advice) | B30: After | C30: Now (job) | D30: Why
A31: 累積航空哩程的信用卡值得辦嗎？ | B31: 想累積航空哩程，哪一張信用卡最值得辦？ | C31: Competitive | D31: Generic advice → added a bank comparison; now tests share of voice vs rivals.
A32: 數位帳戶適合小資族管理薪水嗎？ | B32: 小資族想用數位帳戶管理薪水，哪一家銀行的數位帳戶最適合？ | C32: Competitive | D32: Generic advice → added a bank comparison; now tests share of voice vs rivals.
A33: 台幣定存和活存哪一個比較適合短期資金？ | B33: 短期資金想放國泰世華，台幣定存和數位帳戶活存哪一個比較划算？ | C33: Representation | D33: Generic advice → named a Cathay product; now tests how the AI represents it.
A34: 定存要選機動利率還是固定利率比較好？ | B34: 在國泰世華做台幣定存，機動利率和固定利率哪一個比較划算？ | C34: Representation | D34: Generic advice → named a Cathay product; now tests how the AI represents it.
A35: 一筆短期閒置資金，放定存還是數位帳戶活存比較划算？ | B35: 一筆短期閒置資金想放高利活存，哪一家銀行的數位帳戶利率最高？ | C35: Competitive | D35: Generic advice → added a bank comparison; now tests share of voice vs rivals.
A36: 想做短期美元配置，外幣定存和外幣活存哪一個比較適合？ | B36: 想做短期美元配置，國泰世華的外幣定存和外幣活存哪一個比較適合？ | C36: Representation | D36: Generic advice → named a Cathay product; now tests how the AI represents it.
A37: 第一次做外幣投資，該從哪一種外幣存款開始？ | B37: 第一次想做外幣定存，國泰世華有哪些適合新手的幣別和方案？ | C37: Representation | D37: Generic advice → named a Cathay product; now tests how the AI represents it.
A38: 剛開始理財的小資族，第一步該怎麼做？ | B38: 小資族想開始理財，國泰世華的數位帳戶和定期定額基金哪一個適合當第一步？ | C38: Representation | D38: Generic advice → named a Cathay product; now tests how the AI represents it.
A39: 想幫小孩開始理財，可以怎麼規劃？ | B39: 國泰世華有沒有適合幫小孩開始理財的兒童帳戶或親子方案？ | C39: Representation | D39: Generic advice → named a Cathay product; now tests how the AI represents it.
A40: 每月有固定結餘，該放定存還是投資基金？ | B40: 每月有固定結餘想投資，哪一家銀行的定期定額基金平台手續費最低？ | C40: Competitive | D40: Generic advice → added a bank comparison; now tests share of voice vs rivals.
A41: 第一次開戶要注意哪些事情？ | B41: 第一次想線上開戶，哪一家銀行的流程對新手最友善？ | C41: Competitive | D41: Generic advice → added a bank comparison; now tests share of voice vs rivals.
A43: Branded to match “is our content good?” intent (33)
A44: 33 pure-informational prompts about Cathay's own processes were branded (named 國泰世華); they show as Branded = Yes, Job = Content, so they are graded on Owned Citations / Content Visibility.
A46: Kept unbranded — discovery / generic concept (6)
A47: Prompt | B47: Why kept unbranded
...
